Workbook
Name BM_Dates: T_Bench[Date]
Name BM_Value: T_Bench[Benchmark_Value]
Name FundDates: T_FundNAV[Date]
Name FundNAV: T_FundNAV[Fund_NAV]
Name MAR_Annual: Inputs!$C$3
Name RF_Annual: Inputs!$C$2
Name SIP_Amt: Inputs!$C$4

Sheet Inputs
B1: Symbol | C1: value
A2: Risk-Free Rate (annual, %) | B2: IN10Y | C2: =VLOOKUP(B2,$A$11:$D$27,4,0) -> 6.506
A3: Minimum Acceptable Return (annual, %) | C3: 0 | E3: Mutual funds do not give profit every month In some months NAV goes up, in some months it goes down. This is normal and not a problem in long-term SIP.If we set MAR = 6%, then even a small normal drop looks “bad” in calculation. To avoid wrongly marking normal movements as bad, we set:MAR = 0%
A4: SIP Amount (₹ per month) | C4: 1000
A5: Assume Dates Are Month-End? (Yes/No) | C5: Yes
A9: Risk Free Rate
A10: https://in.tradingview.com/symbols/TVC-IN10Y/
A11: Symbol | B11: Term to Maturity | C11: Maturity date | D11: Risk Free Rate
A12: IN03MY | B12: 3 months | C12: Feb 6, 2026 | D12: 5.42
A13: IN06MY | B13: 6 months | C13: May 8, 2026 | D13: 5.562
A14: IN01Y | B14: 1 year | C14: Oct 29, 2026 | D14: 5.552
A15: INO2Y | B15: 2 years | C15: Apr 10, 2028 | D15: 5.776
A16: IN03Y | B16: 3 years | C16: Oct 23, 2028 | D16: 5.838
A17: IN04Y | B17: 4 years | C17: Dec 23, 2029 | D17: 6.085
A18: IN05Y | B18: 5 years | C18: Jul 21, 2030 | D18: 6.165
A19: IN06Y | B19: 6 years | C19: Jan 17, 2032 | D19: 6.407
A20: INO7Y | B20: 7 years | C20: Jul 14, 2032 | D20: 6.397
A21: IN08Y | B21: 8 years | C21: Aug 14, 2033 | D21: 6.535
A22: INO9Y | B22: 9 years | C22: Oct 7, 2034 | D22: 6.56
A23: IN10Y | B23: 10 years | C23: May 5, 2035 | D23: 6.506
... A27: IN14Y | B27: 14 years | C27: Nov 18, 2039 | D27: 6.854

Sheet NAV_Data
A1: Date | B1: Fund_NAV | D1: https://www.easternfin.com/mf-research/historical-NAV/Quant%20Mid%20Cap%20Fund%20-%20Growth%20Option%20-%20Direct%20Plan?start_date=11-11-2020&end_date=11-11-2025
A2: =Clean_NAV!E3 -> 43861 | B2: =Clean_NAV!F3 -> 40.2568 | D2: Quant Multi Asset Allocation Fund-GROWTH OPTION-Direct Plan
A3: =Clean_NAV!E4 -> 43890 | B3: =Clean_NAV!F4 -> 39.1444
A4: =Clean_NAV!E5 -> 43921 | B4: =Clean_NAV!F5 -> 30.8608
A5: =Clean_NAV!E6 -> 43951 | B5: =Clean_NAV!F6 -> 34.4411
A6: =Clean_NAV!E7 -> 43982 | B6: =Clean_NAV!F7 -> 34.0255
A7: =Clean_NAV!E8 -> 44012 | B7: =Clean_NAV!F8 -> 36.0392
A8: =Clean_NAV!E9 -> 44043 | B8: =Clean_NAV!F9 -> 43.5881
A9: =Clean_NAV!E10 -> 44074 | B9: =Clean_NAV!F10 -> 45.2749
A10: =Clean_NAV!E11 -> 44104 | B10: =Clean_NAV!F11 -> 46.1049
A11: =Clean_NAV!E12 -> 44135 | B11: =Clean_NAV!F12 -> 47.6283
A12: =Clean_NAV!E13 -> 44165 | B12: =Clean_NAV!F13 -> 48.4269
A13: =Clean_NAV!E14 -> 44196 | B13: =Clean_NAV!F14 -> 50.5929
A14: =Clean_NAV!E15 -> 44227 | B14: =Clean_NAV!F15 -> 49.9191
... A72: =Clean_NAV!E73 -> 45972 | B72: =Clean_NAV!F73 -> 163.467

Sheet Benchmark_Data
A1: Date | B1: Benchmark_Value
A2: =Clean_Benchmark!D2 -> 43861 | B2: =Clean_Benchmark!E2 -> 14804.57
A3: =Clean_Benchmark!D3 -> 43890 | B3: =Clean_Benchmark!E3 -> 13875.34
A4: =Clean_Benchmark!D4 -> 43921 | B4: =Clean_Benchmark!E4 -> 10167.46
A5: =Clean_Benchmark!D5 -> 43951 | B5: =Clean_Benchmark!E5 -> 12072.43
A6: =Clean_Benchmark!D6 -> 43982 | B6: =Clean_Benchmark!E6 -> 11793.53
A7: =Clean_Benchmark!D7 -> 44012 | B7: =Clean_Benchmark!E7 -> 12783.45
A8: =Clean_Benchmark!D8 -> 44043 | B8: =Clean_Benchmark!E8 -> 13654.79
A9: =Clean_Benchmark!D9 -> 44074 | B9: =Clean_Benchmark!E9 -> 14179.34
A10: =Clean_Benchmark!D10 -> 44104 | B10: =Clean_Benchmark!E10 -> 14139.78
A11: =Clean_Benchmark!D11 -> 44135 | B11: =Clean_Benchmark!E11 -> 14521.56
A12: =Clean_Benchmark!D12 -> 44165 | B12: =Clean_Benchmark!E12 -> 16255.62
A13: =Clean_Benchmark!D13 -> 44196 | B13: =Clean_Benchmark!E13 -> 17470.79
... A71: =Clean_Benchmark!D71 -> 45961 | B71: =Clean_Benchmark!E71 -> 37822.45
A72: =Clean_NAV!E73 -> 45972 | B72: =Clean_Benchmark!E72 -> 37794.11

Sheet Calc
A1: Helper/Series | B1: Formula / Notes
A2: Monthly Risk-Free (decimal) | B2: =RF_Annual/100/12 -> 0.0054216667
A3: Monthly MAR (decimal) | B3: =MAR_Annual/100/12 -> 0
C4: Rp
A5: Date | B5: Fund_NAV | C5: Fund_Monthly_Return | D5: Benchmark_Value | E5: BM_Monthly_Return | F5: Excess_Fund (r - rf/12) | G5: Excess_BM (r - rf/12) | H5: Active_Return (Fund - BM) | I5: Running_Peak_NAV | J5: Drawdown
A6: =INDEX(FundDates,ROW()-5) -> 43861 | B6: =INDEX(FundNAV,ROW()-5) -> 40.2568 | C6: 0 | D6: =IFERROR(INDEX(BM_Value,MATCH(A6,BM_Dates,0)),NA()) -> 14804.57 | E6: 0 | F6: =IF(ISNUMBER(C6),C6-$B$2,NA()) -> -0.0054216667 | G6: =IF(ISNUMBER(E6),E6-$B$2,NA()) -> -0.0054216667 | H6: =IF(AND(ISNUMBER(C6),ISNUMBER(E6)),C6-E6,NA()) -> 0 | I6: =IF(ROW()=6,B6,MAX(B6,I5)) -> 40.2568 | J6: =B6/I6-1 -> 0
A7: =INDEX(FundDates,ROW()-5) -> 43890 | B7: =INDEX(FundNAV,ROW()-5) -> 39.1444 | C7: =IF(ROW()=6,NA(),INDEX(FundNAV,ROW()-5)/INDEX(FundNAV,ROW()-6-1)-1) -> 0.086161735 | D7: =IFERROR(INDEX(BM_Value,MATCH(A7,BM_Dates,0)),NA()) -> 13875.34 | E7: =IF(OR(ROW()=6,ISNA(D7)),NA(),D7/D6-1) -> -0.06276643 | F7: =IF(ISNUMBER(C7),C7-$B$2,NA()) -> 0.080740068 | G7: =IF(ISNUMBER(E7),E7-$B$2,NA()) -> -0.068188096 | H7: =IF(AND(ISNUMBER(C7),ISNUMBER(E7)),C7-E7,NA()) -> 0.14892816 | I7: =IF(ROW()=6,B7,MAX(B7,I6)) -> 40.2568 | J7: =IF(I7=0,NA(),B7/I7-1) -> -0.027632599
A8: =INDEX(FundDates,ROW()-5) -> 43921 | B8: =INDEX(FundNAV,ROW()-5) -> 30.8608 | C8: =IF(ROW()=6,NA(),INDEX(FundNAV,ROW()-5)/INDEX(FundNAV,ROW()-6-1)-1) -> -0.23340156 | D8: =IFERROR(INDEX(BM_Value,MATCH(A8,BM_Dates,0)),NA()) -> 10167.46 | E8: =IF(OR(ROW()=6,ISNA(D8)),NA(),D8/D7-1) -> -0.26722805 | F8: =IF(ISNUMBER(C8),C8-$B$2,NA()) -> -0.23882323 | G8: =IF(ISNUMBER(E8),E8-$B$2,NA()) -> -0.27264971 | H8: =IF(AND(ISNUMBER(C8),ISNUMBER(E8)),C8-E8,NA()) -> 0.033826484 | I8: =IF(ROW()=6,B8,MAX(B8,I7)) -> 40.2568 | J8: =IF(I8=0,NA(),B8/I8-1) -> -0.23340156
A9: =INDEX(FundDates,ROW()-5) -> 43951 | B9: =INDEX(FundNAV,ROW()-5) -> 34.4411 | C9: =IF(ROW()=6,NA(),INDEX(FundNAV,ROW()-5)/INDEX(FundNAV,ROW()-6-1)-1) -> -0.12015256 | D9: =IFERROR(INDEX(BM_Value,MATCH(A9,BM_Dates,0)),NA()) -> 12072.43 | E9: =IF(OR(ROW()=6,ISNA(D9)),NA(),D9/D8-1) -> 0.18735948 | F9: =IF(ISNUMBER(C9),C9-$B$2,NA()) -> -0.12557423 | G9: =IF(ISNUMBER(E9),E9-$B$2,NA()) -> 0.18193781 | H9: =IF(AND(ISNUMBER(C9),ISNUMBER(E9)),C9-E9,NA()) -> -0.30751204 | I9: =IF(ROW()=6,B9,MAX(B9,I8)) -> 40.2568 | J9: =IF(I9=0,NA(),B9/I9-1) -> -0.14446503
A10: =INDEX(FundDates,ROW()-5) -> 43982 | B10: =INDEX(FundNAV,ROW()-5) -> 34.0255 | C10: =IF(ROW()=6,NA(),INDEX(FundNAV,ROW()-5)/INDEX(FundNAV,ROW()-6-1)-1) -> 0.10254757 | D10: =IFERROR(INDEX(BM_Value,MATCH(A10,BM_Dates,0)),NA()) -> 11793.53 | E10: =IF(OR(ROW()=6,ISNA(D10)),NA(),D10/D9-1) -> -0.023102225 | F10: =IF(ISNUMBER(C10),C10-$B$2,NA()) -> 0.097125902 | G10: =IF(ISNUMBER(E10),E10-$B$2,NA()) -> -0.028523892 | H10: =IF(AND(ISNUMBER(C10),ISNUMBER(E10)),C10-E10,NA()) -> 0.12564979 | I10: =IF(ROW()=6,B10,MAX(B10,I9)) -> 40.2568 | J10: =IF(I10=0,NA(),B10/I10-1) -> -0.15478876
A11: =INDEX(FundDates,ROW()-5) -> 44012 | B11: =INDEX(FundNAV,ROW()-5) -> 36.0392 | C11: =IF(ROW()=6,NA(),INDEX(FundNAV,ROW()-5)/INDEX(FundNAV,ROW()-6-1)-1) -> 0.046400957 | D11: =IFERROR(INDEX(BM_Value,MATCH(A11,BM_Dates,0)),NA()) -> 12783.45 | E11: =IF(OR(ROW()=6,ISNA(D11)),NA(),D11/D10-1) -> 0.083937549 | F11: =IF(ISNUMBER(C11),C11-$B$2,NA()) -> 0.04097929 | G11: =IF(ISNUMBER(E11),E11-$B$2,NA()) -> 0.078515882 | H11: =IF(AND(ISNUMBER(C11),ISNUMBER(E11)),C11-E11,NA()) -> -0.037536592 | I11: =IF(ROW()=6,B11,MAX(B11,I10)) -> 40.2568 | J11: =IF(I11=0,NA(),B11/I11-1) -> -0.10476739
A12: =INDEX(FundDates,ROW()-5) -> 44043 | B12: =INDEX(FundNAV,ROW()-5) -> 43.5881 | C12: =IF(ROW()=6,NA(),INDEX(FundNAV,ROW()-5)/INDEX(FundNAV,ROW()-6-1)-1) -> 0.28104216 | D12: =IFERROR(INDEX(BM_Value,MATCH(A12,BM_Dates,0)),NA()) -> 13654.79 | E12: =IF(OR(ROW()=6,ISNA(D12)),NA(),D12/D11-1) -> 0.068161568 | F12: =IF(ISNUMBER(C12),C12-$B$2,NA()) -> 0.27562049 | G12: =IF(ISNUMBER(E12),E12-$B$2,NA()) -> 0.062739902 | H12: =IF(AND(ISNUMBER(C12),ISNUMBER(E12)),C12-E12,NA()) -> 0.21288059 | I12: =IF(ROW()=6,B12,MAX(B12,I11)) -> 43.5881 | J12: =IF(I12=0,NA(),B12/I12-1) -> 0
A13: =INDEX(FundDates,ROW()-5) -> 44074 | B13: =INDEX(FundNAV,ROW()-5) -> 45.2749 | C13: =IF(ROW()=6,NA(),INDEX(FundNAV,ROW()-5)/INDEX(FundNAV,ROW()-6-1)-1) -> 0.25626817 | D13: =IFERROR(INDEX(BM_Value,MATCH(A13,BM_Dates,0)),NA()) -> 14179.34 | E13: =IF(OR(ROW()=6,ISNA(D13)),NA(),D13/D12-1) -> 0.038415091 | F13: =IF(ISNUMBER(C13),C13-$B$2,NA()) -> 0.25084651 | G13: =IF(ISNUMBER(E13),E13-$B$2,NA()) -> 0.032993424 | H13: =IF(AND(ISNUMBER(C13),ISNUMBER(E13)),C13-E13,NA()) -> 0.21785308 | I13: =IF(ROW()=6,B13,MAX(B13,I12)) -> 45.2749 | J13: =IF(I13=0,NA(),B13/I13-1) -> 0
A14: =INDEX(FundDates,ROW()-5) -> 44104 | B14: =INDEX(FundNAV,ROW()-5) -> 46.1049 | C14: =IF(ROW()=6,NA(),INDEX(FundNAV,ROW()-5)/INDEX(FundNAV,ROW()-6-1)-1) -> 0.05774053 | D14: =IFERROR(INDEX(BM_Value,MATCH(A14,BM_Dates,0)),NA()) -> 14139.78 | E14: =IF(OR(ROW()=6,ISNA(D14)),NA(),D14/D13-1) -> -0.0027899747 | F14: =IF(ISNUMBER(C14),C14-$B$2,NA()) -> 0.052318863 | G14: =IF(ISNUMBER(E14),E14-$B$2,NA()) -> -0.0082116414 | H14: =IF(AND(ISNUMBER(C14),ISNUMBER(E14)),C14-E14,NA()) -> 0.060530505 | I14: =IF(ROW()=6,B14,MAX(B14,I13)) -> 46.1049 | J14: =IF(I14=0,NA(),B14/I14-1) -> 0
A15: =INDEX(FundDates,ROW()-5) -> 44135 | B15: =INDEX(FundNAV,ROW()-5) -> 47.6283 | C15: =IF(ROW()=6,NA(),INDEX(FundNAV,ROW()-5)/INDEX(FundNAV,ROW()-6-1)-1) -> 0.051980236 | D15: =IFERROR(INDEX(BM_Value,MATCH(A15,BM_Dates,0)),NA()) -> 14521.56 | E15: =IF(OR(ROW()=6,ISNA(D15)),NA(),D15/D14-1) -> 0.02700042 | F15: =IF(ISNUMBER(C15),C15-$B$2,NA()) -> 0.04655857 | G15: =IF(ISNUMBER(E15),E15-$B$2,NA()) -> 0.021578753 | H15: =IF(AND(ISNUMBER(C15),ISNUMBER(E15)),C15-E15,NA()) -> 0.024979816 | I15: =IF(ROW()=6,B15,MAX(B15,I14)) -> 47.6283 | J15: =IF(I15=0,NA(),B15/I15-1) -> 0
A16: =INDEX(FundDates,ROW()-5) -> 44165 | B16: =INDEX(FundNAV,ROW()-5) -> 48.4269 | C16: =IF(ROW()=6,NA(),INDEX(FundNAV,ROW()-5)/INDEX(FundNAV,ROW()-6-1)-1) -> 0.05036341 | D16: =IFERROR(INDEX(BM_Value,MATCH(A16,BM_Dates,0)),NA()) -> 16255.62 | E16: =IF(OR(ROW()=6,ISNA(D16)),NA(),D16/D15-1) -> 0.11941279 | F16: =IF(ISNUMBER(C16),C16-$B$2,NA()) -> 0.044941744 | G16: =IF(ISNUMBER(E16),E16-$B$2,NA()) -> 0.11399112 | H16: =IF(AND(ISNUMBER(C16),ISNUMBER(E16)),C16-E16,NA()) -> -0.06904938 | I16: =IF(ROW()=6,B16,MAX(B16,I15)) -> 48.4269 | J16: =IF(I16=0,NA(),B16/I16-1) -> 0
A17: =INDEX(FundDates,ROW()-5) -> 44196 | B17: =INDEX(FundNAV,ROW()-5) -> 50.5929 | C17: =IF(ROW()=6,NA(),INDEX(FundNAV,ROW()-5)/INDEX(FundNAV,ROW()-6-1)-1) -> 0.062244506 | D17: =IFERROR(INDEX(BM_Value,MATCH(A17,BM_Dates,0)),NA()) -> 17470.79 | E17: =IF(OR(ROW()=6,ISNA(D17)),NA(),D17/D16-1) -> 0.074753839 | F17: =IF(ISNUMBER(C17),C17-$B$2,NA()) -> 0.056822839 | G17: =IF(ISNUMBER(E17),E17-$B$2,NA()) -> 0.069332172 | H17: =IF(AND(ISNUMBER(C17),ISNUMBER(E17)),C17-E17,NA()) -> -0.012509333 | I17: =IF(ROW()=6,B17,MAX(B17,I16)) -> 50.5929 | J17: =IF(I17=0,NA(),B17/I17-1) -> 0
A18: =INDEX(FundDates,ROW()-5) -> 44227 | B18: =INDEX(FundNAV,ROW()-5) -> 49.9191 | C18: =IF(ROW()=6,NA(),INDEX(FundNAV,ROW()-5)/INDEX(FundNAV,ROW()-6-1)-1) -> 0.030813453 | D18: =IFERROR(INDEX(BM_Value,MATCH(A18,BM_Dates,0)),NA()) -> 17147.27 | E18: =IF(OR(ROW()=6,ISNA(D18)),NA(),D18/D17-1) -> -0.018517766 | F18: =IF(ISNUMBER(C18),C18-$B$2,NA()) -> 0.025391786 | G18: =IF(ISNUMBER(E18),E18-$B$2,NA()) -> -0.023939433 | H18: =IF(AND(ISNUMBER(C18),ISNUMBER(E18)),C18-E18,NA()) -> 0.049331219 | I18: =IF(ROW()=6,B18,MAX(B18,I17)) -> 50.5929 | J18: =IF(I18=0,NA(),B18/I18-1) -> -0.013318074
... A76: =INDEX(FundDates,ROW()-5) -> 45972 | B76: =INDEX(FundNAV,ROW()-5) -> 163.467 | C76: =IF(ROW()=6,NA(),INDEX(FundNAV,ROW()-5)/INDEX(FundNAV,ROW()-6-1)-1) -> 0.04690371 | D76: =IFERROR(INDEX(BM_Value,MATCH(A76,BM_Dates,0)),NA()) -> 37794.11 | E76: =IF(OR(ROW()=6,ISNA(D76)),NA(),D76/D75-1) -> -0.00074929043 | F76: =IF(ISNUMBER(C76),C76-$B$2,NA()) -> 0.041482043 | G76: =IF(ISNUMBER(E76),E76-$B$2,NA()) -> -0.0061709571 | H76: =IF(AND(ISNUMBER(C76),ISNUMBER(E76)),C76-E76,NA()) -> 0.047653 | I76: =IF(ROW()=6,B76,MAX(B76,I75)) -> 163.467 | J76: =IF(I76=0,NA(),B76/I76-1) -> 0

Sheet SIP
A1: Date | B1: NAV | C1: SIP Amount | D1: Units Bought | E1: Cumulative Units | F1: Value at NAV | G1: Cashflow for XIRR
A2: =INDEX(FundDates,ROW()-1) -> 43861 | B2: =INDEX(FundNAV,ROW()-1) -> 40.2568 | C2: =SIP_Amt -> 1000 | D2: =IFERROR(C2/B2,NA()) -> 24.840524 | E2: =IF(ROW()=2,D2,IFERROR(E1+D2,NA())) -> 24.840524 | F2: =IFERROR(E2*B2,NA()) -> 1000 | G2: =-C2 -> -1000 | I2: Current Units | J2: =LOOKUP(2,1/(E:E<>""),E:E) -> 908.66361
A3: =INDEX(FundDates,ROW()-1) -> 43890 | B3: =INDEX(FundNAV,ROW()-1) -> 39.1444 | C3: =SIP_Amt -> 1000 | D3: =IFERROR(C3/B3,NA()) -> 25.546438 | E3: =IFERROR(E2+D3,NA()) -> 50.386962 | F3: =IFERROR(E3*B3,NA()) -> 1972.3674 | G3: =-C3 -> -1000 | I3: Last NAV | J3: =LOOKUP(2,1/(B:B<>""),B:B) -> 163.467
A4: =INDEX(FundDates,ROW()-1) -> 43921 | B4: =INDEX(FundNAV,ROW()-1) -> 30.8608 | C4: =SIP_Amt -> 1000 | D4: =IFERROR(C4/B4,NA()) -> 32.403567 | E4: =IFERROR(E3+D4,NA()) -> 82.790529 | F4: =IFERROR(E4*B4,NA()) -> 2554.982 | G4: =-C4 -> -1000 | I4: Current Value | J4: =J2*J3 -> 148536.51
A5: =INDEX(FundDates,ROW()-1) -> 43951 | B5: =INDEX(FundNAV,ROW()-1) -> 34.4411 | C5: =SIP_Amt -> 1000 | D5: =IFERROR(C5/B5,NA()) -> 29.035077 | E5: =IFERROR(E4+D5,NA()) -> 111.82561 | F5: =IFERROR(E5*B5,NA()) -> 3851.3969 | G5: =-C5 -> -1000 | I5: SIP XIRR | J5: =XIRR(G2:G74, A2:A74) -> 0.26191097
A6: =INDEX(FundDates,ROW()-1) -> 43982 | B6: =INDEX(FundNAV,ROW()-1) -> 34.0255 | C6: =SIP_Amt -> 1000 | D6: =IFERROR(C6/B6,NA()) -> 29.389722 | E6: =IFERROR(E5+D6,NA()) -> 141.21533 | F6: =IFERROR(E6*B6,NA()) -> 4804.9222 | G6: =-C6 -> -1000
A7: =INDEX(FundDates,ROW()-1) -> 44012 | B7: =INDEX(FundNAV,ROW()-1) -> 36.0392 | C7: =SIP_Amt -> 1000 | D7: =IFERROR(C7/B7,NA()) -> 27.747564 | E7: =IFERROR(E6+D7,NA()) -> 168.96289 | F7: =IFERROR(E7*B7,NA()) -> 6089.2875 | G7: =-C7 -> -1000
A8: =INDEX(FundDates,ROW()-1) -> 44043 | B8: =INDEX(FundNAV,ROW()-1) -> 43.5881 | C8: =SIP_Amt -> 1000 | D8: =IFERROR(C8/B8,NA()) -> 22.942042 | E8: =IFERROR(E7+D8,NA()) -> 191.90493 | F8: =IFERROR(E8*B8,NA()) -> 8364.7715 | G8: =-C8 -> -1000
A9: =INDEX(FundDates,ROW()-1) -> 44074 | B9: =INDEX(FundNAV,ROW()-1) -> 45.2749 | C9: =SIP_Amt -> 1000 | D9: =IFERROR(C9/B9,NA()) -> 22.087293 | E9: =IFERROR(E8+D9,NA()) -> 213.99223 | F9: =IFERROR(E9*B9,NA()) -> 9688.4767 | G9: =-C9 -> -1000
A10: =INDEX(FundDates,ROW()-1) -> 44104 | B10: =INDEX(FundNAV,ROW()-1) -> 46.1049 | C10: =SIP_Amt -> 1000 | D10: =IFERROR(C10/B10,NA()) -> 21.689669 | E10: =IFERROR(E9+D10,NA()) -> 235.6819 | F10: =IFERROR(E10*B10,NA()) -> 10866.09 | G10: =-C10 -> -1000
A11: =INDEX(FundDates,ROW()-1) -> 44135 | B11: =INDEX(FundNAV,ROW()-1) -> 47.6283 | C11: =SIP_Amt -> 1000 | D11: =IFERROR(C11/B11,NA()) -> 20.99592 | E11: =IFERROR(E10+D11,NA()) -> 256.67782 | F11: =IFERROR(E11*B11,NA()) -> 12225.128 | G11: =-C11 -> -1000
A12: =INDEX(FundDates,ROW()-1) -> 44165 | B12: =INDEX(FundNAV,ROW()-1) -> 48.4269 | C12: =SIP_Amt -> 1000 | D12: =IFERROR(C12/B12,NA()) -> 20.64968 | E12: =IFERROR(E11+D12,NA()) -> 277.3275 | F12: =IFERROR(E12*B12,NA()) -> 13430.111 | G12: =-C12 -> -1000
A13: =INDEX(FundDates,ROW()-1) -> 44196 | B13: =INDEX(FundNAV,ROW()-1) -> 50.5929 | C13: =SIP_Amt -> 1000 | D13: =IFERROR(C13/B13,NA()) -> 19.765619 | E13: =IFERROR(E12+D13,NA()) -> 297.09312 | F13: =IFERROR(E13*B13,NA()) -> 15030.802 | G13: =-C13 -> -1000
A14: =INDEX(FundDates,ROW()-1) -> 44227 | B14: =INDEX(FundNAV,ROW()-1) -> 49.9191 | C14: =SIP_Amt -> 1000 | D14: =IFERROR(C14/B14,NA()) -> 20.032412 | E14: =IFERROR(E13+D14,NA()) -> 317.12553 | F14: =IFERROR(E14*B14,NA()) -> 15830.621 | G14: =-C14 -> -1000
A15: =INDEX(FundDates,ROW()-1) -> 44255 | B15: =INDEX(FundNAV,ROW()-1) -> 52.4131 | C15: =SIP_Amt -> 1000 | D15: =IFERROR(C15/B15,NA()) -> 19.0792 | E15: =IFERROR(E14+D15,NA()) -> 336.20473 | F15: =IFERROR(E15*B15,NA()) -> 17621.532 | G15: =-C15 -> -1000
A16: =INDEX(FundDates,ROW()-1) -> 44286 | B16: =INDEX(FundNAV,ROW()-1) -> 54.2065 | C16: =SIP_Amt -> 1000 | D16: =IFERROR(C16/B16,NA()) -> 18.447972 | E16: =IFERROR(E15+D16,NA()) -> 354.6527 | F16: =IFERROR(E16*B16,NA()) -> 19224.482 | G16: =-C16 -> -1000
A17: =INDEX(FundDates,ROW()-1) -> 44316 | B17: =INDEX(FundNAV,ROW()-1) -> 61.4837 | C17: =SIP_Amt -> 1000 | D17: =IFERROR(C17/B17,NA()) -> 16.264473 | E17: =IFERROR(E16+D17,NA()) -> 370.91717 | F17: =IFERROR(E17*B17,NA()) -> 22805.36 | G17: =-C17 -> -1000
... A71: =INDEX(FundDates,ROW()-1) -> 45961 | B71: =INDEX(FundNAV,ROW()-1) -> 162.8732 | C71: =SIP_Amt -> 1000 | D71: =IFERROR(C71/B71,NA()) -> 6.1397455 | E71: =IFERROR(E70+D71,NA()) -> 902.54617 | F71: =IFERROR(E71*B71,NA()) -> 147000.58 | G71: =-C71 -> -1000
A72: =INDEX(FundDates,ROW()-1) -> 45972 | B72: =INDEX(FundNAV,ROW()-1) -> 163.467 | C72: =SIP_Amt -> 1000 | D72: =IFERROR(C72/B72,NA()) -> 6.1174427 | E72: =IFERROR(E71+D72,NA()) -> 908.66361 | F72: =IFERROR(E72*B72,NA()) -> 148536.51 | G72: =F72 -> 148536.51
A2003: Final Value at Last Date | G2003: =J4 -> 148536.51

Sheet Summary
A1: Metric | B1: Formula | C1: Value | D1: PERFORMANCE QUALITY | E1: Report
A2: Data Points (months) | B2: Count of return periods | C2: =COUNT(NAV_Data!$A:$A) -> 71 | O2: ✅ PERFORMANCE QUALITY — 1-LINE CRITERIA FOR EACH METRIC
A3: Start Date | B3: First NAV date | C3: =INDEX(NAV_Data!A:A, MATCH(MIN(NAV_Data!A:A), NAV_Data!A:A, 0)) -> 43861
A4: End Date | B4: Last NAV date | C4: =INDEX(NAV_Data!A:A, MATCH(MAX(NAV_Data!A:A), NAV_Data!A:A, 0)) -> 45972 | O4: Absolute Return (Fund) – Good if above 100% over multi-year period.
A5: Start Nav | B5: First NAV value | C5: =INDEX(NAV_Data!B:B, MATCH(MIN(NAV_Data!A:A), NAV_Data!A:A, 0)) -> 40.2568
A6: End Nav | B6: Last NAV value | C6: =INDEX(NAV_Data!B:B, MATCH(MAX(NAV_Data!A:A), NAV_Data!A:A, 0)) -> 163.467 | O6: CAGR (Fund, annual) – Good if 12%–18%+, excellent if >18%.
A7: RETURN METRICS
A8: Absolute Return (Fund) | B8: (End NAV – Start NAV) / Start NAV | C8: =(C6 - C5) / C5 -> 3.0606059 | D8: Good if above 100% over multi-year period. | E8: GOOD
A9: CAGR (Fund, annual) | B9: (End NAV / Start NAV)^(1/Years) – 1 | C9: =(C6/C5)^(12/C2)-1 -> 0.26724453 | D9: Good if 12%–18%+, excellent if >18%. | E9: GOOD | O9: CAGR (Benchmark, annual) – Good if 10%–14%.
A10: CAGR (Benchmark, annual) | B10: (End BM / Start BM)^(1/Years) – 1 | C10: =(Benchmark_Data!B72/Benchmark_Data!B2)^(12/C2)-1 -> 0.17163819 | D10: No “good/bad”; benchmark return varies by index — use only for comparison. | E10: AVERAGE
A11: Average Monthly Return (Fund) | B11: Mean of Fund_Monthly_Return | C11: =AVERAGE(Calc!$C:$C) -> 0.044831027 | D11: Good if >0.8% per month (0.008). | E11: AVERAGE | O11: Average Monthly Return (Fund) – Good if >0.8% per month (0.008).
A12: RISK METRICS
A13: Stdev Monthly (Fund) | B13: σ_monthly = Standard deviation of Fund_Monthly_Return | C13: =_xlfn.STDEV.S(Calc!$C:$C) -> 0.079297349 | D13: Good if <6% (0.06); lower = more stable. | E13: AVERAGE
A14: Stdev Annualized (Fund) | B14: σ_annual = σ_monthly × √12 | C14: =C13* SQRT(12) -> 0.27469407 | D14: Good if <20%; >25% = high risk. | E14: BAD | O14: Stdev Monthly (Fund) – Good if <6% (0.06); lower = more stable.
A15: Sharpe Ratio (Fund) | B15: Sharpe = (Rp – Rf) / σ | C15: =AVERAGE(Calc!$F:$F) / C13 -> 0.49698207 | D15: Good if >100% , acceptable if 50%–100% | E15: AVERAGE
A16: DOWNSIDE RISK
A17: Downside Deviation Monthly vs MAR | B17: min(Rt – MAR, 0) → square → average → sqrt | C17: {=SQRT(AVERAGE(IF(Calc!$C:$C<0, Calc!$C:$C^2)))} -> 0.083181248 | D17: Good if <3% (0.03). | E17: AVERAGE | O17: Stdev Annualized (Fund) – Good if <20%; >25% = high risk.
A18: Downside Deviation Annualized | B18: σd = sqrt( average( min(Rt – MAR, 0)^2 ) ) | C18: =C17 * SQRT(12) -> 0.28814829 | D18: Good if <10%.* | E18: AVERAGE
A19: Sortino Ratio (Fund) | B19: Sortino = (Rp – Rf) / σd | C19: =AVERAGE(Calc!$F:$F) /C18 -> 0.13676763 | D19: Good if >100% , acceptable if 50%–100% | E19: AVERAGE | O19: Sharpe Ratio (Fund) – Good if >1.0, acceptable if 0.5–1.0.
A20: FACTOR METRICS
A21: Beta (vs Benchmark) | B21: Cov(Fund, Benchmark) / Var(Benchmark) | C21: =_xlfn.COVARIANCE.P(Calc!$C:$C, Calc!$E:$E) / _xlfn.VAR.P(Calc!$E:$E) -> 0.58176786 | D21: Good if between 70% and 100%; <70% = low-risk fund. | E21: AVERAGE
A22: Alpha Monthly (excess) | B22: α = FundExcess – Beta × BenchmarkExcess | C22: =AVERAGE(Calc!$F:$F) - (C21 * AVERAGE(Calc!$G:$G)) -> 0.033850352 | D22: Good if >0; strong if >0.5% (0.005). | E22: AVERAGE | O22: Downside Deviation Monthly – Good if <3% (0.03).
A23: Alpha Annualized | B23: (1 + α_monthly)^12 – 1 | C23: =(1 + C22)^12 - 1 -> 0.49104984 | D23: Good if >3%; excellent if >5%.* | E23: GOOD
A24: R-Squared | B24: RSQ(mutual fund's returns, BM_Monthly_Return) | C24: =RSQ(Calc!$C:$C, Calc!$E:$E) -> 0.17543501 | D24: Healthy if 70%–95%; <50% = low benchmark relevance. | E24: BAD | O24: Downside Deviation Annualized – Good if <10%.*
A25: TRACKING METRICS
A26: Tracking Error (annualized) | B26: StdDev(Active Return) × √12 | C26: =_xlfn.STDEV.S(Calc!$H:$H) * SQRT(12) -> 0.26279373 | D26: Good if 2%–6%; >8% = very high deviation. | E26: AVERAGE
A27: Information Ratio | B27: IR = Avg Active Return / Tracking Error | C27: =AVERAGE(Calc!$H:$H) / _xlfn.STDEV.S(Calc!$H:$H) -> 0.39353012 | D27: Good if >50%; excellent if >100%. | E27: GOOD | O27: Sortino Ratio (Fund) – Good if >1.0, acceptable if 0.5–1.0.
A28: TREYNOR & DRAWDOWN
A29: Treynor Ratio | B29: Treynor = (Rp – Rf) / Beta | C29: =AVERAGE(Calc!$F:$F) / C21 -> 0.067740698 | D29: Good if higher than benchmark (positive & consistently rising). | E29: AVERAGE
A30: Max Drawdown | B30: Min(Drawdown Series) | C30: =MIN(Calc!$J:$J) -> -0.23340156 | D30: Good if better than –25% (less negative). | E30: AVERAGE | O30: Beta (vs Benchmark) – Good if between 0.7 and 1.0; <0.7 = low-risk fund.
A31: Calmar Ratio | B31: Calmar = CAGR / |MaxDD| | C31: =C9/-C30 -> 1.1449989 | D31: Good if >0.5; excellent if >1.0. | E31: GOOD
A32: CAPTURE RATIOS
A33: Upside Capture Ratio | B33: Avg(FundReturns | Benchmark>0) / Avg(BMReturns | BM>0) | C33: {=AVERAGE(IF(Calc!$E:$E>0, Calc!$C:$C)) / AVERAGE(IF(Calc!$E:$E>0, Calc!$E:$E))} -> 1.5517235 | D33: Good if 100%–130%; >130% excellent. | E33: GOOD | O33: Alpha Monthly (excess) – Good if >0; strong if >0.5% (0.005).
A34: Downside Capture Ratio | B34: Avg(FundReturns | Benchmark<0) / Avg(BMReturns | BM<0) | C34: {=AVERAGE(IF(Calc!$E:$E<0, Calc!$C:$C)) / AVERAGE(IF(Calc!$E:$E<0, Calc!$E:$E))} -> -0.077575162 | D34: Good if <90%; <70% excellent. | E34: GOOD
A35: Hit Ratio (% months Fund > BM) | B35: Months FundReturn > BMReturn | C35: {=SUMPRODUCT(--(Calc!C5:C76 > Calc!E5:E76)) / (ROWS(Calc!C5:C76))} -> 0.66666667 | D35: Good if >50%; excellent if >60%. | E35: GOOD | O35: Alpha Annualized – Good if >3%; excellent if >5%.*
A36: DISTRIBUTION METRICS
A37: Skewness (monthly returns) | B37: Skew(Rp) | C37: =SKEW(Calc!$C:$C) -> 0.1098036 | D37: Good if positive (right-skewed). | E37: AVERAGE
A38: Kurtosis (monthly returns) | B38: Kurtosis(Rp) | C38: =KURT(Calc!$C:$C) -> 3.1492158 | D38: Good if between 2–4; >7 = too much tail risk. | E38: AVERAGE | O38: R-Squared – Healthy if 70%–95%; <50% = low benchmark relevance.
A39: Historical VaR 95% (monthly) | B39: 5th Percentile of Returns | C39: =_xlfn.PERCENTILE.INC(Calc!$C:$C, 0.05) -> -0.068522288 | D39: Good if not worse than –5%.* | E39: AVERAGE
A40: SIP METRICS
...

Sheet Clean_NAV
A1: Quant Multi Asset Allocation Fund-GROWTH OPTION-Direct Plan
A2: NAV Date | B2: NAV (Rs) | C2: MonthEnd | D2: nav | E2: MonthEnd | F2: Actual Nav
A3: 43831 | B3: 39.7675 | C3: =EOMONTH(A3,0) -> 43861 | D3: =INDEX($B$3:$B$2001, MATCH($C3, $A$3:$A$2001, 1)) -> 40.2568 | E3: 43861 | F3: =VLOOKUP(E3,$C$2:$D$1449,2,0) -> 40.2568
A4: 43832 | B4: 40.0834 | C4: =EOMONTH(A4,0) -> 43861 | D4: =INDEX($B$3:$B$2001, MATCH($C4, $A$3:$A$2001, 1)) -> 40.2568 | E4: 43890 | F4: =VLOOKUP(E4,$C$2:$D$1449,2,0) -> 39.1444
A5: 43833 | B5: 40.0099 | C5: =EOMONTH(A5,0) -> 43861 | D5: =INDEX($B$3:$B$2001, MATCH($C5, $A$3:$A$2001, 1)) -> 40.2568 | E5: 43921 | F5: =VLOOKUP(E5,$C$2:$D$1449,2,0) -> 30.8608
A6: 43836 | B6: 39.3285 | C6: =EOMONTH(A6,0) -> 43861 | D6: =INDEX($B$3:$B$2001, MATCH($C6, $A$3:$A$2001, 1)) -> 40.2568 | E6: 43951 | F6: =VLOOKUP(E6,$C$2:$D$1449,2,0) -> 34.4411
A7: 43837 | B7: 39.5412 | C7: =EOMONTH(A7,0) -> 43861 | D7: =INDEX($B$3:$B$2001, MATCH($C7, $A$3:$A$2001, 1)) -> 40.2568 | E7: 43982 | F7: =VLOOKUP(E7,$C$2:$D$1449,2,0) -> 34.0255
A8: 43838 | B8: 39.5614 | C8: =EOMONTH(A8,0) -> 43861 | D8: =INDEX($B$3:$B$2001, MATCH($C8, $A$3:$A$2001, 1)) -> 40.2568 | E8: 44012 | F8: =VLOOKUP(E8,$C$2:$D$1449,2,0) -> 36.0392
A9: 43839 | B9: 40.0048 | C9: =EOMONTH(A9,0) -> 43861 | D9: =INDEX($B$3:$B$2001, MATCH($C9, $A$3:$A$2001, 1)) -> 40.2568 | E9: 44043 | F9: =VLOOKUP(E9,$C$2:$D$1449,2,0) -> 43.5881
A10: 43840 | B10: 40.154 | C10: =EOMONTH(A10,0) -> 43861 | D10: =INDEX($B$3:$B$2001, MATCH($C10, $A$3:$A$2001, 1)) -> 40.2568 | E10: 44074 | F10: =VLOOKUP(E10,$C$2:$D$1449,2,0) -> 45.2749
A11: 43843 | B11: 40.4195 | C11: =EOMONTH(A11,0) -> 43861 | D11: =INDEX($B$3:$B$2001, MATCH($C11, $A$3:$A$2001, 1)) -> 40.2568 | E11: 44104 | F11: =VLOOKUP(E11,$C$2:$D$1449,2,0) -> 46.1049
A12: 43844 | B12: 40.5304 | C12: =EOMONTH(A12,0) -> 43861 | D12: =INDEX($B$3:$B$2001, MATCH($C12, $A$3:$A$2001, 1)) -> 40.2568 | E12: 44135 | F12: =VLOOKUP(E12,$C$2:$D$1449,2,0) -> 47.6283
A13: 43845 | B13: 40.2529 | C13: =EOMONTH(A13,0) -> 43861 | D13: =INDEX($B$3:$B$2001, MATCH($C13, $A$3:$A$2001, 1)) -> 40.2568 | E13: 44165 | F13: =VLOOKUP(E13,$C$2:$D$1449,2,0) -> 48.4269
A14: 43846 | B14: 40.0545 | C14: =EOMONTH(A14,0) -> 43861 | D14: =INDEX($B$3:$B$2001, MATCH($C14, $A$3:$A$2001, 1)) -> 40.2568 | E14: 44196 | F14: =VLOOKUP(E14,$C$2:$D$1449,2,0) -> 50.5929
... A72: 43936 | B72: 34.7716 | C72: =EOMONTH(A72,0) -> 43951 | D72: =INDEX($B$3:$B$2001, MATCH($C72, $A$3:$A$2001, 1)) -> 34.4411 | E72: 45961 | F72: =VLOOKUP(E72,$C$2:$D$1449,2,0) -> 162.8732
A73: 43937 | B73: 34.7883 | C73: =EOMONTH(A73,0) -> 43951 | D73: =INDEX($B$3:$B$2001, MATCH($C73, $A$3:$A$2001, 1)) -> 34.4411 | E73: 45972 | F73: 163.467
A74: 43938 | B74: 34.5068 | C74: =EOMONTH(A74,0) -> 43951 | D74: =INDEX($B$3:$B$2001, MATCH($C74, $A$3:$A$2001, 1)) -> 34.4411
A75: 43941 | B75: 34.5137 | C75: =EOMONTH(A75,0) -> 43951 | D75: =INDEX($B$3:$B$2001, MATCH($C75, $A$3:$A$2001, 1)) -> 34.4411
A76: 43942 | B76: 34.2035 | C76: =EOMONTH(A76,0) -> 43951 | D76: =INDEX($B$3:$B$2001, MATCH($C76, $A$3:$A$2001, 1)) -> 34.4411
A77: 43943 | B77: 33.9168 | C77: =EOMONTH(A77,0) -> 43951 | D77: =INDEX($B$3:$B$2001, MATCH($C77, $A$3:$A$2001, 1)) -> 34.4411
A78: 43944 | B78: 34.2565 | C78: =EOMONTH(A78,0) -> 43951 | D78: =INDEX($B$3:$B$2001, MATCH($C78, $A$3:$A$2001, 1)) -> 34.4411
A79: 43945 | B79: 34.178 | C79: =EOMONTH(A79,0) -> 43951 | D79: =INDEX($B$3:$B$2001, MATCH($C79, $A$3:$A$2001, 1)) -> 34.4411
A80: 43948 | B80: 34.1898 | C80: =EOMONTH(A80,0) -> 43951 | D80: =INDEX($B$3:$B$2001, MATCH($C80, $A$3:$A$2001, 1)) -> 34.4411
A81: 43949 | B81: 34.174 | C81: =EOMONTH(A81,0) -> 43951 | D81: =INDEX($B$3:$B$2001, MATCH($C81, $A$3:$A$2001, 1)) -> 34.4411
A82: 43950 | B82: 34.5862 | C82: =EOMONTH(A82,0) -> 43951 | D82: =INDEX($B$3:$B$2001, MATCH($C82, $A$3:$A$2001, 1)) -> 34.4411
A83: 43951 | B83: 34.4411 | C83: =EOMONTH(A83,0) -> 43951 | D83: =INDEX($B$3:$B$2001, MATCH($C83, $A$3:$A$2001, 1)) -> 34.4411
A84: 43955 | B84: 34.6219 | C84: =EOMONTH(A84,0) -> 43982 | D84: =INDEX($B$3:$B$2001, MATCH($C84, $A$3:$A$2001, 1)) -> 34.0255
A85: 43956 | B85: 34.1838 | C85: =EOMONTH(A85,0) -> 43982 | D85: =INDEX($B$3:$B$2001, MATCH($C85, $A$3:$A$2001, 1)) -> 34.0255
... A1449: 45972 | B1449: 163.467 | C1449: =EOMONTH(A1449,0) -> 45991 | D1449: =INDEX($B$3:$B$2001, MATCH($C1449, $A$3:$A$2001, 1)) -> 163.467

Sheet Nifty 500 TRI
A1: Date | B1: Price | C1: Open | D1: High | E1: Low | F1: Vol. | G1: Change %
A2: 43831 | B2: 14843.29 | C2: 14843.29 | D2: 14843.29 | E2: 14843.29 | G2: 0.0016
A3: 43832 | B3: 14980.54 | C3: 14980.54 | D3: 14980.54 | E3: 14980.54 | G3: 0.0092
A4: 43833 | B4: 14922.99 | C4: 14922.99 | D4: 14922.99 | E4: 14922.99 | G4: -0.0038
A5: 43836 | B5: 14631.41 | C5: 14631.41 | D5: 14631.41 | E5: 14631.41 | G5: -0.0195
A6: 43837 | B6: 14718.47 | C6: 14718.47 | D6: 14718.47 | E6: 14718.47 | G6: 0.006
A7: 43838 | B7: 14698.65 | C7: 14698.65 | D7: 14698.65 | E7: 14698.65 | G7: -0.0013
A8: 43839 | B8: 14926.45 | C8: 14926.45 | D8: 14926.45 | E8: 14926.45 | G8: 0.0155
A9: 43840 | B9: 14977.61 | C9: 14977.61 | D9: 14977.61 | E9: 14977.61 | G9: 0.0034
A10: 43843 | B10: 15074.41 | C10: 15074.41 | D10: 15074.41 | E10: 15074.41 | G10: 0.0065
A11: 43844 | B11: 15124.47 | C11: 15124.47 | D11: 15124.47 | E11: 15124.47 | G11: 0.0033
A12: 43845 | B12: 15141.31 | C12: 15141.31 | D12: 15141.31 | E12: 15141.31 | G12: 0.0011
A13: 43846 | B13: 15175.81 | C13: 15175.81 | D13: 15175.81 | E13: 15175.81 | G13: 0.0023
... A1432: 45972 | B1432: 37794.11 | C1432: 37794.11 | D1432: 37794.11 | E1432: 37794.11 | G1432: 0.0036

Sheet Clean_Benchmark
A1: NAV Date | B1: NAV (Rs) | C1: MonthEnd | D1: MonthEnd | E1: Actual Nav
A2: 43831 | B2: 14843.29 | C2: =EOMONTH(A2,0) -> 43861 | D2: {=_xlfn.UNIQUE(_xlfn._xlws.SORT(C2:C2000))} -> 43861 | E2: {=LOOKUP(2,1/($C$2:$C$2000=D2),$B$2:$B$2000)} -> 14804.57
A3: 43832 | B3: 14980.54 | C3: =EOMONTH(A3,0) -> 43861 | D3: 43890 | E3: {=LOOKUP(2,1/($C$2:$C$2000=D3),$B$2:$B$2000)} -> 13875.34
A4: 43833 | B4: 14922.99 | C4: =EOMONTH(A4,0) -> 43861 | D4: 43921 | E4: {=LOOKUP(2,1/($C$2:$C$2000=D4),$B$2:$B$2000)} -> 10167.46
A5: 43836 | B5: 14631.41 | C5: =EOMONTH(A5,0) -> 43861 | D5: 43951 | E5: {=LOOKUP(2,1/($C$2:$C$2000=D5),$B$2:$B$2000)} -> 12072.43
A6: 43837 | B6: 14718.47 | C6: =EOMONTH(A6,0) -> 43861 | D6: 43982 | E6: {=LOOKUP(2,1/($C$2:$C$2000=D6),$B$2:$B$2000)} -> 11793.53
A7: 43838 | B7: 14698.65 | C7: =EOMONTH(A7,0) -> 43861 | D7: 44012 | E7: {=LOOKUP(2,1/($C$2:$C$2000=D7),$B$2:$B$2000)} -> 12783.45
A8: 43839 | B8: 14926.45 | C8: =EOMONTH(A8,0) -> 43861 | D8: 44043 | E8: {=LOOKUP(2,1/($C$2:$C$2000=D8),$B$2:$B$2000)} -> 13654.79
A9: 43840 | B9: 14977.61 | C9: =EOMONTH(A9,0) -> 43861 | D9: 44074 | E9: {=LOOKUP(2,1/($C$2:$C$2000=D9),$B$2:$B$2000)} -> 14179.34
A10: 43843 | B10: 15074.41 | C10: =EOMONTH(A10,0) -> 43861 | D10: 44104 | E10: {=LOOKUP(2,1/($C$2:$C$2000=D10),$B$2:$B$2000)} -> 14139.78
A11: 43844 | B11: 15124.47 | C11: =EOMONTH(A11,0) -> 43861 | D11: 44135 | E11: {=LOOKUP(2,1/($C$2:$C$2000=D11),$B$2:$B$2000)} -> 14521.56
A12: 43845 | B12: 15141.31 | C12: =EOMONTH(A12,0) -> 43861 | D12: 44165 | E12: {=LOOKUP(2,1/($C$2:$C$2000=D12),$B$2:$B$2000)} -> 16255.62
A13: 43846 | B13: 15175.81 | C13: =EOMONTH(A13,0) -> 43861 | D13: 44196 | E13: {=LOOKUP(2,1/($C$2:$C$2000=D13),$B$2:$B$2000)} -> 17470.79
A14: 43847 | B14: 15188.79 | C14: =EOMONTH(A14,0) -> 43861 | D14: 44227 | E14: {=LOOKUP(2,1/($C$2:$C$2000=D14),$B$2:$B$2000)} -> 17147.27
... A72: 43937 | B72: 11166.67 | C72: =EOMONTH(A72,0) -> 43951 | D72: 45991 | E72: {=LOOKUP(2,1/($C$2:$C$2000=D72),$B$2:$B$2000)} -> 37794.11
A73: 43938 | B73: 11471.14 | C73: =EOMONTH(A73,0) -> 43951 | D73: 0
A74: 43941 | B74: 11471.44 | C74: =EOMONTH(A74,0) -> 43951
A75: 43942 | B75: 11141.94 | C75: =EOMONTH(A75,0) -> 43951
A76: 43943 | B76: 11349.73 | C76: =EOMONTH(A76,0) -> 43951
A77: 43944 | B77: 11487.6 | C77: =EOMONTH(A77,0) -> 43951
A78: 43945 | B78: 11288.98 | C78: =EOMONTH(A78,0) -> 43951
A79: 43948 | B79: 11455.42 | C79: =EOMONTH(A79,0) -> 43951
A80: 43949 | B80: 11558.67 | C80: =EOMONTH(A80,0) -> 43951
A81: 43950 | B81: 11747.42 | C81: =EOMONTH(A81,0) -> 43951
A82: 43951 | B82: 12072.43 | C82: =EOMONTH(A82,0) -> 43951
A83: 43955 | B83: 11445.71 | C83: =EOMONTH(A83,0) -> 43982
A84: 43956 | B84: 11335.14 | C84: =EOMONTH(A84,0) -> 43982
A85: 43957 | B85: 11414.15 | C85: =EOMONTH(A85,0) -> 43982
... A1432: 45972 | B1432: 37794.11 | C1432: =EOMONTH(A1432,0) -> 45991
